Workbook
Name _10_Abr_09: festivos!$A$89:$A$800
Name Días_festivos: festivos!$A$2:$A$800

Sheet festivos
A1: Días festivos
A2: 36161
A3: 36196
A4: 36251
A5: 36252
A6: 36285
A7: 36404
A8: 36419
A9: 36466
A10: 36606
A11: 36636
A12: 36637
A13: 36647
... A500: 53328

Sheet indices
B1: MEXBOL Index | C1: INDU Index | D1: SPX Index | E1: CCMP Index | F1: RTY Index | G1: SPTSX Index | H1: IBOV Index | I1: SX5E Index | J1: ASX Index | K1: UKX Index | L1: DAX Index | M1: CAC Index | N1: IBEX Index | O1: NKY Index | P1: SHSZ300 Index | Q1: SHCOMP Index | R1: SZCOMP Index | S1: HSI Index | T1: SENSEX Index | U1: KOSPI Index | V1: MXWOSM Index | W1: VIX Index
B2: MX | C2: US | D2: US | E2: US | F2: US | G2: CA | H2: BZ | I2: EC | J2: GB | K2: GB | L2: GE | M2: FR | N2: SP | O2: JN | P2: CH | Q2: CH | R2: CH | S2: HK | T2: IN | U2: SK | V2: MULT | W2: MULT
A3: =COLUMN(A3) -> 1 | B3: =COLUMN(B3) -> 2 | C3: =COLUMN(C3) -> 3 | D3: =COLUMN(D3) -> 4 | E3: =COLUMN(E3) -> 5 | F3: =COLUMN(F3) -> 6 | G3: =COLUMN(G3) -> 7 | H3: =COLUMN(H3) -> 8 | ... W3: =COLUMN(W3) -> 23
A4: 32904 | B4: 444.75 | C4: 2590.54 | D4: 329.08 | E4: 415.81 | G4: 3704.5 | H4: n.d. | J4: 1167.15 | K4: 2337.3 | L4: 1822.78 | M4: 1882.88 | N4: 2841.6 | O4: 37188.95 | U4: 896.16 | W4: 25.36
A5: 32904 | B5: 473.02 | C5: 2627.25 | D5: 329.08 | E5: 425.83 | G5: 3686.8 | H5: n.d. | J5: 1122.26 | K5: 2255.4 | L5: 1809.92 | M5: 1849.68 | N5: 2841.6 | O5: 34591.99 | U5: 861.59 | W5: 25.36
A6: 32904 | B6: 489.62 | C6: 2707.21 | D6: 329.08 | E6: 435.54 | G6: 3639.6 | H6: n.d. | J6: 1114.94 | K6: 2247.9 | L6: 1968.55 | M6: 1971.79 | N6: 2841.6 | O6: 29980.45 | U6: 845.98 | W6: 25.36
A7: 32904 | B7: 473.02 | C7: 2627.25 | D7: 329.08 | E7: 425.83 | G7: 3686.8 | H7: n.d. | J7: 1122.26 | K7: 2255.4 | L7: 1809.92 | M7: 1849.68 | N7: 2841.6 | O7: 34591.99 | U7: 861.59 | W7: 25.36
A8: 32904 | B8: 489.62 | C8: 2707.21 | D8: 329.08 | E8: 435.54 | G8: 3639.6 | H8: n.d. | J8: 1114.94 | K8: 2247.9 | L8: 1968.55 | M8: 1971.79 | N8: 2841.6 | O8: 29980.45 | U8: 845.98 | W8: 25.36
A9: 32904 | B9: 473.02 | C9: 2627.25 | D9: 329.08 | E9: 425.83 | G9: 3686.8 | H9: n.d. | J9: 1122.26 | K9: 2255.4 | L9: 1809.92 | M9: 1849.68 | N9: 2841.6 | O9: 34591.99 | U9: 861.59 | W9: 25.36
A10: 32904 | B10: 489.62 | C10: 2707.21 | D10: 329.08 | E10: 435.54 | G10: 3639.6 | H10: n.d. | J10: 1114.94 | K10: 2247.9 | L10: 1968.55 | M10: 1971.79 | N10: 2841.6 | O10: 29980.45 | U10: 845.98 | W10: 25.36
A11: 32904 | B11: 473.02 | C11: 2627.25 | D11: 329.08 | E11: 425.83 | G11: 3686.8 | H11: n.d. | J11: 1122.26 | K11: 2255.4 | L11: 1809.92 | M11: 1849.68 | N11: 2841.6 | O11: 34591.99 | U11: 861.59 | W11: 25.36
A12: 32904 | B12: 489.62 | C12: 2707.21 | D12: 329.08 | E12: 435.54 | G12: 3639.6 | H12: n.d. | J12: 1114.94 | K12: 2247.9 | L12: 1968.55 | M12: 1971.79 | N12: 2841.6 | O12: 29980.45 | U12: 845.98 | W12: 25.36
A13: 32904 | B13: 473.02 | C13: 2627.25 | D13: 329.08 | E13: 425.83 | G13: 3686.8 | H13: n.d. | J13: 1122.26 | K13: 2255.4 | L13: 1809.92 | M13: 1849.68 | N13: 2841.6 | O13: 34591.99 | U13: 861.59 | W13: 25.36
A14: 32904 | B14: 489.62 | C14: 2707.21 | D14: 329.08 | E14: 435.54 | G14: 3639.6 | H14: n.d. | J14: 1114.94 | K14: 2247.9 | L14: 1968.55 | M14: 1971.79 | N14: 2841.6 | O14: 29980.45 | U14: 845.98 | W14: 25.36
A15: 32904 | B15: 473.02 | C15: 2627.25 | D15: 329.08 | E15: 425.83 | G15: 3686.8 | H15: n.d. | J15: 1122.26 | K15: 2255.4 | L15: 1809.92 | M15: 1849.68 | N15: 2841.6 | O15: 34591.99 | U15: 861.59 | W15: 25.36
... A205: 33235 | B205: 628.79 | C205: 2629.21 | D205: 328.72 | E205: 371.2 | G205: 3237.5 | H205: n.d. | J205: 1038.43 | K205: 2160.4 | L205: 1398.23 | M205: 1517.93 | N205: 2248.8 | O205: 23848.71 | U205: 696.11 | W205: 25.05
A206: 33240 | B206: 625.47 | C206: 2610.64 | D206: 326.45 | E206: 372.19 | G206: 3239.4 | H206: n.d. | J206: 1025.13 | K206: 2128.3 | L206: 1366.1 | M206: 1505.1 | N206: 2207.6 | O206: 23848.71 | T206: 999.26 | U206: 696.11 | W206: 26.62
A207: 33241 | B207: 616.19 | C207: 2573.51 | D207: 321.91 | E207: 367.51 | G207: 3221.8 | H207: n.d. | J207: 1019.78 | K207: 2117.8 | L207: 1366.65 | M207: 1539.5 | N207: 2222.4 | O207: 23848.71 | T207: 982.35 | U207: 679.75 | W207: 27.93
A208: 33242 | B208: 622.2 | C208: 2566.09 | D208: 321 | E208: 367.24 | G208: 3216.6 | H208: n.d. | J208: 1023.21 | K208: 2126.1 | L208: 1396.07 | M208: 1547.66 | N208: 2248.7 | O208: 24069.18 | T208: #N/A | U208: 697.62 | W208: 27.19
A209: 33245 | B209: 599.21 | C209: 2522.77 | D209: 315.44 | E209: 360.24 | G209: 3201.1 | H209: n.d. | J209: 1017.62 | K209: 2113.4 | L209: 1358.16 | M209: 1507.87 | N209: 2225.8 | O209: 23736.57 | T209: 1010.77 | U209: 676.65 | W209: 28.95
A210: 33246 | B210: 599.38 | C210: 2509.41 | D210: 314.9 | E210: 359 | G210: 3182.5 | H210: n.d. | J210: 1011.39 | K210: 2099.9 | L210: 1353.95 | M210: 1502.77 | N210: 2205.9 | O210: 22897.84 | T210: #N/A | U210: 659.68 | W210: 30.38
A211: 33247 | B211: 591.21 | C211: 2470.3 | D211: 311.49 | E211: 357.45 | G211: 3169.7 | H211: n.d. | J211: 1023.43 | K211: 2128.9 | L211: 1375.16 | M211: 1552.19 | N211: 2264.8 | O211: 22969.27 | T211: 1008.52 | U211: 660.39 | W211: 33.3
A212: 33248 | B212: 587.11 | C212: 2498.76 | D212: 314.53 | E212: 361.92 | G212: 3196.9 | H212: n.d. | J212: 1013.81 | K212: 2108.7 | L212: 1383.4 | M212: 1507.09 | N212: 2197.5 | O212: 23047.36 | T212: #N/A | U212: 635.46 | W212: 31.33
A213: 33249 | B213: 583.5 | C213: 2501.49 | D213: 315.23 | E213: 361.8 | G213: 3183.6 | H213: n.d. | J213: 1012.23 | K213: 2105.8 | L213: 1382.26 | M213: 1494.94 | N213: 2195.5 | O213: 23241.02 | T213: 1034.3 | U213: 627.7 | W213: 32.63
A214: 33252 | B214: 567.09 | C214: 2483.91 | D214: 312.49 | E214: 355.75 | G214: 3167.6 | H214: n.d. | J214: 1000.17 | K214: 2080.8 | L214: 1331.25 | M214: 1441.17 | N214: 2151.2 | O214: 23213.23 | T214: 1017.72 | U214: 652.25 | W214: 36.2
A215: 33253 | B215: 573.23 | C215: 2490.59 | D215: 313.73 | E215: 357.3 | G215: 3162 | H215: n.d. | J215: 995.42 | K215: 2071.1 | L215: 1325.62 | M215: 1457.27 | N215: 2162.9 | O215: 23213.23 | T215: #N/A | U215: 624.62 | W215: 36.16
A216: 33254 | B216: 569.55 | C216: 2508.91 | D216: 316.17 | E216: 365.2 | G216: 3164.5 | H216: n.d. | J216: 987.46 | K216: 2054.9 | L216: 1322.68 | M216: 1457.77 | N216: 2159.3 | O216: 22442.7 | T216: #N/A | U216: 613.34 | W216: 33.2
A217: 33255 | B217: 609.02 | C217: 2623.51 | D217: 327.97 | E217: 375.81 | G217: 3201.7 | H217: n.d. | J217: 1008.6 | K217: 2104.6 | L217: 1414.58 | M217: 1560.47 | N217: 2312.1 | O217: 23446.81 | T217: #N/A | U217: 641.42 | W217: 27.45
A218: 33256 | B218: 605.81 | C218: 2646.78 | D218: 332.23 | E218: 376.99 | G218: 3210.5 | H218: n.d. | J218: 1006.8 | K218: 2102.7 | L218: 1405.06 | M218: 1560.27 | N218: 2277.2 | O218: 23808.3 | T218: #N/A | U218: 667.35 | W218: 25.39
A219: 33259 | B219: 596.07 | C219: 2629.21 | D219: 331.06 | E219: 379.7 | G219: 3205.3 | H219: n.d. | J219: 998.92 | K219: 2084 | L219: 1390.2 | M219: 1553.57 | N219: 2251.2 | O219: 23352.19 | T219: #N/A | U219: 636.91 | W219: 24.33
A220: 33260 | B220: 589.48 | C220: 2603.22 | D220: 328.31 | E220: 379.03 | G220: 3196.8 | H220: n.d. | J220: 996.81 | K220: 2081.6 | L220: 1375.12 | M220: 1548.64 | N220: 2231.5 | O220: 23253.65 | T220: #N/A | U220: 632.92 | W220: 24.9
A221: 33261 | B221: 585.21 | C221: 2619.06 | D221: 330.21 | E221: 383.91 | G221: 3190.6 | H221: n.d. | J221: 996.23 | K221: 2080.5 | L221: 1358.76 | M221: 1522.39 | N221: 2219.4 | O221: 23050.1 | T221: 1001.38 | U221: 625.22 | W221: 23.92
A222: 33262 | B222: 594.25 | C222: 2643.07 | D222: 334.78 | E222: 391.33 | G222: 3212.7 | H222: n.d. | J222: 1004.96 | K222: 2099.5 | L222: 1375.16 | M222: 1553.77 | N222: 2259.5 | O222: 23269.01 | T222: 971.8 | U222: 638.02 | W222: 22.86
A223: 33263 | B223: 601.99 | C223: 2659.41 | D223: 336.07 | E223: 394.28 | G223: 3234 | H223: n.d. | J223: 1006.76 | K223: 2103 | L223: 1382.05 | M223: 1563 | N223: 2276.2 | O223: 23573.25 | T223: 956.11 | U223: 632.95 | W223: 22.2
A224: 33266 | B224: 613.05 | C224: 2654.46 | D224: 336.03 | E224: 396.8 | G224: 3228.7 | H224: n.d. | J224: 1012.72 | K224: 2118 | L224: 1382.68 | M224: 1565.69 | N224: 2291 | O224: 23569.44 | T224: #N/A | U224: 633.93 | W224: 23.05
A225: 33267 | B225: 612.68 | C225: 2662.62 | D225: 335.84 | E225: 400.61 | G225: 3222.3 | H225: n.d. | J225: 1011.57 | K225: 2113.8 | L225: 1380.26 | M225: 1554.49 | N225: 2293.3 | O225: 23460.12 | T225: #N/A | U225: 635.65 | W225: 23.17
A226: 33268 | B226: 619.34 | C226: 2713.12 | D226: 340.91 | E226: 408.53 | G226: 3248.7 | H226: n.d. | J226: 1028.19 | K226: 2152.6 | L226: 1400.73 | M226: 1582.45 | N226: 2346.5 | O226: 23409.61 | T226: #N/A | U226: 638.09 | W226: 21.37
A227: 33269 | B227: 622.99 | C227: 2736.39 | D227: 343.93 | E227: 414.2 | G227: 3273 | H227: n.d. | J227: 1036.24 | K227: 2170.1 | L227: 1420.18 | M227: 1580.67 | N227: 2333.7 | O227: 23293.14 | T227: 982.32 | U227: 635.4 | W227: 20.91
A228: 33270 | B228: 620.55 | C228: 2730.69 | D228: 343.05 | E228: 417.69 | G228: 3293.5 | H228: n.d. | J228: 1035.41 | K228: 2165.8 | L228: 1426.51 | M228: 1578.08 | N228: 2327.9 | O228: 23156.7 | T228: 1021.95 | U228: 632.53 | W228: 21.04
A229: 33273 | B229: 623.86 | C229: 2772.28 | D229: 348.34 | E229: 424.8 | G229: 3328 | H229: n.d. | J229: 1039.76 | K229: 2172.4 | L229: 1435.03 | M229: 1581.73 | N229: 2373.9 | O229: 23287.36 | T229: 1052.04 | U229: 632.79 | W229: 21.86
...
